Workbook

Sheet Midsem
A1: Vivekanand Education Society's Institute of Technology
A2: Department of Information Technology
A3: Academic Year :2024-2025
A5: Subject : Data Structures and Analysis Class : D10A
A6: Subject Teacher :Sairam Konar Semester : III
A7: Number of Students =60
A8: Roll Nos. | B8: 1a (2) | C8: 1b (2) | D8: 1c (2) | E8: 1d (2) | F8: 1e (2) | G8: 1f (2) | H8: Q1 | I8: 2a (5) | J8: 2b (5) | K8: Q2 | L8: 3a (5) | M8: 3b (5) | N8: Q3 | O8: Total
A9: COs | B9: CO1 | C9: CO2 | D9: CO1 | E9: CO2 | F9: CO1 | G9: CO2 | I9: CO2,3 | J9: CO3,4 | L9: CO2,4 | M9: CO1,4 | O9: 20
A10: 1 | B10: 2 | C10: 2 | E10: 1 | F10: 2 | G10: 2 | H10: =ROUND(SUM(B10:G10),0) | I10: 3 | K10: =ROUND(SUM(I10:J10),0) | L10: 4 | N10: =ROUND(SUM(L10:M10),0) | O10: =ROUND(SUM(H10,K10,N10),0)
A11: 2 | B11: 1 | C11: 2 | D11: 2 | E11: 1 | H11: =ROUND(SUM(B11:G11),0) | J11: 4 | K11: =ROUND(SUM(I11:J11),0) | M11: 5 | N11: =ROUND(SUM(L11:M11),0) | O11: =ROUND(SUM(H11,K11,N11),0)
A12: 3 | B12: 2 | C12: 2 | D12: 2 | E12: 2 | F12: 2 | H12: =ROUND(SUM(B12:G12),0) | I12: 5 | K12: =ROUND(SUM(I12:J12),0) | M12: 5 | N12: =ROUND(SUM(L12:M12),0) | O12: =ROUND(SUM(H12,K12,N12),0)
A13: 4 | B13: 1 | F13: 1 | H13: =ROUND(SUM(B13:G13),0) | J13: 2 | K13: =ROUND(SUM(I13:J13),0) | N13: =ROUND(SUM(L13:M13),0) | O13: =ROUND(SUM(H13,K13,N13),0)
A14: 5 | B14: 2 | C14: 2 | E14: 1 | F14: 2 | G14: 2 | H14: =ROUND(SUM(B14:G14),0) | I14: 3 | K14: =ROUND(SUM(I14:J14),0) | L14: 4 | N14: =ROUND(SUM(L14:M14),0) | O14: =ROUND(SUM(H14,K14,N14),0)
A15: 6 | B15: 1 | F15: 1 | H15: =ROUND(SUM(B15:G15),0) | J15: 2 | K15: =ROUND(SUM(I15:J15),0) | N15: =ROUND(SUM(L15:M15),0) | O15: =ROUND(SUM(H15,K15,N15),0)
A16: 7 | B16: 2 | C16: 2 | D16: 2 | E16: 2 | F16: 2 | H16: =ROUND(SUM(B16:G16),0) | I16: 5 | K16: =ROUND(SUM(I16:J16),0) | M16: 5 | N16: =ROUND(SUM(L16:M16),0) | O16: =ROUND(SUM(H16,K16,N16),0)
A17: 8 | B17: 2 | D17: 2 | F17: 2 | H17: =ROUND(SUM(B17:G17),0) | I17: 5 | K17: =ROUND(SUM(I17:J17),0) | M17: 4 | N17: =ROUND(SUM(L17:M17),0) | O17: =ROUND(SUM(H17,K17,N17),0)
A18: 9 | B18: 1 | F18: 1 | H18: =ROUND(SUM(B18:G18),0) | J18: 2 | K18: =ROUND(SUM(I18:J18),0) | N18: =ROUND(SUM(L18:M18),0) | O18: =ROUND(SUM(H18,K18,N18),0)
A19: 10 | B19: 2 | C19: 2 | E19: 1 | F19: 2 | G19: 2 | H19: =ROUND(SUM(B19:G19),0) | I19: 3 | K19: =ROUND(SUM(I19:J19),0) | L19: 4 | N19: =ROUND(SUM(L19:M19),0) | O19: =ROUND(SUM(H19,K19,N19),0)
A20: 11 | B20: 2 | D20: 2 | F20: 2 | H20: =ROUND(SUM(B20:G20),0) | I20: 5 | K20: =ROUND(SUM(I20:J20),0) | M20: 4 | N20: =ROUND(SUM(L20:M20),0) | O20: =ROUND(SUM(H20,K20,N20),0)
A21: 12 | B21: 2 | D21: 2 | F21: 2 | H21: =ROUND(SUM(B21:G21),0) | I21: 5 | K21: =ROUND(SUM(I21:J21),0) | M21: 4 | N21: =ROUND(SUM(L21:M21),0) | O21: =ROUND(SUM(H21,K21,N21),0)
A22: 13 | B22: 1 | C22: 2 | D22: 2 | E22: 1 | H22: =ROUND(SUM(B22:G22),0) | J22: 4 | K22: =ROUND(SUM(I22:J22),0) | M22: 5 | N22: =ROUND(SUM(L22:M22),0) | O22: =ROUND(SUM(H22,K22,N22),0)
A23: 14 | B23: 2 | D23: 2 | F23: 2 | H23: =ROUND(SUM(B23:G23),0) | I23: 5 | K23: =ROUND(SUM(I23:J23),0) | M23: 4 | N23: =ROUND(SUM(L23:M23),0) | O23: =ROUND(SUM(H23,K23,N23),0)
A24: 15 | B24: 2 | C24: 2 | E24: 1 | F24: 2 | G24: 2 | H24: =ROUND(SUM(B24:G24),0) | I24: 3 | K24: =ROUND(SUM(I24:J24),0) | L24: 4 | N24: =ROUND(SUM(L24:M24),0) | O24: =ROUND(SUM(H24,K24,N24),0)
A25: 16 | B25: 2 | D25: 2 | F25: 2 | H25: =ROUND(SUM(B25:G25),0) | I25: 5 | K25: =ROUND(SUM(I25:J25),0) | M25: 4 | N25: =ROUND(SUM(L25:M25),0) | O25: =ROUND(SUM(H25,K25,N25),0)
A26: 17 | B26: 2 | C26: 2 | D26: 2 | E26: 2 | F26: 2 | H26: =ROUND(SUM(B26:G26),0) | I26: 5 | K26: =ROUND(SUM(I26:J26),0) | M26: 5 | N26: =ROUND(SUM(L26:M26),0) | O26: =ROUND(SUM(H26,K26,N26),0)
A27: 18 | B27: 2 | D27: 2 | F27: 2 | H27: =ROUND(SUM(B27:G27),0) | I27: 5 | K27: =ROUND(SUM(I27:J27),0) | M27: 4 | N27: =ROUND(SUM(L27:M27),0) | O27: =ROUND(SUM(H27,K27,N27),0)
A28: 19 | B28: 2 | D28: 2 | F28: 2 | H28: =ROUND(SUM(B28:G28),0) | I28: 5 | K28: =ROUND(SUM(I28:J28),0) | M28: 4 | N28: =ROUND(SUM(L28:M28),0) | O28: =ROUND(SUM(H28,K28,N28),0)
A29: 20 | B29: 2 | C29: 2 | E29: 1 | F29: 2 | G29: 2 | H29: =ROUND(SUM(B29:G29),0) | I29: 3 | K29: =ROUND(SUM(I29:J29),0) | L29: 4 | N29: =ROUND(SUM(L29:M29),0) | O29: =ROUND(SUM(H29,K29,N29),0)
A30: 21 | B30: 2 | D30: 2 | F30: 2 | H30: =ROUND(SUM(B30:G30),0) | I30: 5 | K30: =ROUND(SUM(I30:J30),0) | M30: 4 | N30: =ROUND(SUM(L30:M30),0) | O30: =ROUND(SUM(H30,K30,N30),0)
A31: 22 | B31: 2 | D31: 2 | F31: 2 | H31: =ROUND(SUM(B31:G31),0) | I31: 5 | K31: =ROUND(SUM(I31:J31),0) | M31: 4 | N31: =ROUND(SUM(L31:M31),0) | O31: =ROUND(SUM(H31,K31,N31),0)
A32: 23 | B32: 2 | D32: 2 | F32: 2 | H32: =ROUND(SUM(B32:G32),0) | I32: 5 | K32: =ROUND(SUM(I32:J32),0) | M32: 4 | N32: =ROUND(SUM(L32:M32),0) | O32: =ROUND(SUM(H32,K32,N32),0)
A33: 24 | B33: 1 | F33: 1 | H33: =ROUND(SUM(B33:G33),0) | J33: 2 | K33: =ROUND(SUM(I33:J33),0) | N33: =ROUND(SUM(L33:M33),0) | O33: =ROUND(SUM(H33,K33,N33),0)
A34: 25 | B34: 2 | C34: 2 | E34: 1 | F34: 2 | G34: 2 | H34: =ROUND(SUM(B34:G34),0) | I34: 3 | K34: =ROUND(SUM(I34:J34),0) | L34: 4 | N34: =ROUND(SUM(L34:M34),0) | O34: =ROUND(SUM(H34,K34,N34),0)
A35: 26 | B35: 2 | D35: 2 | F35: 2 | H35: =ROUND(SUM(B35:G35),0) | I35: 5 | K35: =ROUND(SUM(I35:J35),0) | M35: 4 | N35: =ROUND(SUM(L35:M35),0) | O35: =ROUND(SUM(H35,K35,N35),0)
A36: 27 | B36: 2 | D36: 2 | F36: 2 | H36: =ROUND(SUM(B36:G36),0) | I36: 5 | K36: =ROUND(SUM(I36:J36),0) | M36: 4 | N36: =ROUND(SUM(L36:M36),0) | O36: =ROUND(SUM(H36,K36,N36),0)
A37: 28 | B37: 1 | C37: 2 | D37: 2 | E37: 1 | H37: =ROUND(SUM(B37:G37),0) | J37: 4 | K37: =ROUND(SUM(I37:J37),0) | M37: 5 | N37: =ROUND(SUM(L37:M37),0) | O37: =ROUND(SUM(H37,K37,N37),0)
A38: 29 | B38: 2 | D38: 2 | F38: 2 | H38: =ROUND(SUM(B38:G38),0) | I38: 5 | K38: =ROUND(SUM(I38:J38),0) | M38: 4 | N38: =ROUND(SUM(L38:M38),0) | O38: =ROUND(SUM(H38,K38,N38),0)
A39: 30 | B39: 2 | C39: 2 | E39: 1 | F39: 2 | G39: 2 | H39: =ROUND(SUM(B39:G39),0) | I39: 3 | K39: =ROUND(SUM(I39:J39),0) | L39: 4 | N39: =ROUND(SUM(L39:M39),0) | O39: =ROUND(SUM(H39,K39,N39),0)
A40: 31 | B40: 2 | D40: 2 | F40: 2 | H40: =ROUND(SUM(B40:G40),0) | I40: 5 | K40: =ROUND(SUM(I40:J40),0) | M40: 4 | N40: =ROUND(SUM(L40:M40),0) | O40: =ROUND(SUM(H40,K40,N40),0)
A41: 32 | B41: 2 | D41: 2 | F41: 2 | H41: =ROUND(SUM(B41:G41),0) | I41: 5 | K41: =ROUND(SUM(I41:J41),0) | M41: 4 | N41: =ROUND(SUM(L41:M41),0) | O41: =ROUND(SUM(H41,K41,N41),0)
...

Sheet Endsem
A1: Roll No. | B1: ESE(TH) (Max Marks: 60)
B2: ALL Qs
B3: CO1,2,3,4,5,6
A4: 1 | B4: 36
A5: 2 | B5: 40
A6: 3 | B6: 45
A7: 4 | B7: 58
A8: 5 | B8: 60
A9: 6 | B9: 40
A10: 7 | B10: 25
A11: 8 | B11: 30
A12: 9 | B12: 38
A13: 10 | B13: 32
A14: 11 | B14: 45
A15: 12 | B15: 46
... A63: 60 | B63: 22
A64: Count(Attempted) | B64: =COUNT(B4:B63)
A65: Average Marks | B65: =ROUND(AVERAGE(B4:B63), 0)
A66: Count(>=60%) | B66: =COUNTIF(B4:B63, ">=36.0")
A67: % Count(>=60% w.r.t appeared) | B67: =ROUND(B66 / B64 * 100, 1)
A68: Count(>=Average Marks of class) | B68: =COUNTIF(B4:B63, ">="&B65)
A69: % Count(>=Average Marks of class w.r.t appeared) | B69: =ROUND(B68 / B64 * 100, 1)
A70: AL(Based on >=60% Count) (All COs) | B70: =IF(B67<60, 1, IF(AND(B67>59, B67<70), 2, IF(AND(B67>69, B67<80), 3, 4)))
A73: COs | B73: AL
A74: CO1 | B74: =IF(B67<60, 1, IF(AND(B67>59, B67<70), 2, IF(AND(B67>69, B67<80), 3, 4)))
A75: CO2 | B75: =IF(B67<60, 1, IF(AND(B67>59, B67<70), 2, IF(AND(B67>69, B67<80), 3, 4)))
A76: CO3 | B76: =IF(B67<60, 1, IF(AND(B67>59, B67<70), 2, IF(AND(B67>69, B67<80), 3, 4)))
A77: CO4 | B77: =IF(B67<60, 1, IF(AND(B67>59, B67<70), 2, IF(AND(B67>69, B67<80), 3, 4)))
A78: CO5 | B78: =IF(B67<60, 1, IF(AND(B67>59, B67<70), 2, IF(AND(B67>69, B67<80), 3, 4)))
A79: CO6 | B79: =IF(B67<60, 1, IF(AND(B67>59, B67<70), 2, IF(AND(B67>69, B67<80), 3, 4)))

Sheet CA1
A1: Type :NPTEL Course
A3: CA Marksheet
A4: Maximum Marks = 10
A5: Roll No. | B5: CA1
B6: CO1,2,3
A7: 1 | B7: 5
A8: 2 | B8: 10
A9: 3 | B9: 7
A10: 4 | B10: 8
A11: 5 | B11: 9
A12: 6 | B12: 7
A13: 7 | B13: 5
A14: 8 | B14: 5
A15: 9 | B15: 6
A16: 10 | B16: 7
A17: 11 | B17: 5
A18: 12 | B18: 10
... A66: 60 | B66: 7
A67: Count(Attempted) | B67: =COUNT(B7:B66)
A68: Average Marks | B68: =ROUND(AVERAGE(B7:B66), 0)
A69: Count(>=40%) | B69: =COUNTIF(B7:B66, ">=4.0")
A70: % Count(>=40% w.r.t appeared) | B70: =ROUND(B69 / B67 * 100, 1)
A71: Count(>=Average Marks of class) | B71: =COUNTIF(B7:B66, ">="&B68)
A72: % Count(>=Average Marks of class w.r.t appeared) | B72: =ROUND(B71 / B67 * 100, 1)
A73: AL(Based on >=40% Count) (All COs) | B73: =IF(B70<60, 1, IF(AND(B70>59, B70<70), 2, IF(AND(B70>69, B70<80), 3, 4)))
B76: COs | C76: AL
B77: CO1 | C77: =ROUND(AVERAGE(B73),1)
B78: CO2 | C78: =ROUND(AVERAGE(B73),1)
B79: CO3 | C79: =ROUND(AVERAGE(B73),1)
B80: CO4 | C80: -
B81: CO5 | C81: -
B82: CO6 | C82: -

Sheet CA2
A1: Type : Quiz Total Questions :4 Maximum Marks for each question = 2
A2: Roll No. | B2: Name | C2: Q1 | D2: Q2 | E2: Q3 | F2: Q4
A3: CO --> | C3: CO5 | D3: CO6 | E3: CO5 | F3: CO6
A4: 1 | C4: 2 | D4: 1 | E4: 2 | F4: 1
A5: 2 | C5: 1 | D5: 2 | E5: 1 | F5: 2
A6: 3 | C6: 1 | E6: 1
A7: 4 | D7: 2 | F7: 2
A8: 5 | D8: 1 | F8: 1
A9: 6 | C9: 2 | E9: 2
A10: 7 | D10: 1
A11: 8 | E11: 1
A12: 9
A13: 10 | C13: 2 | D13: 2 | E13: 2 | F13: 2
A14: 11 | C14: 2 | D14: 1 | E14: 2 | F14: 1
A15: 12 | C15: 1 | D15: 2 | E15: 1 | F15: 2
A16: 13 | C16: 1 | E16: 1
A17: 14 | D17: 2 | F17: 2
A18: 15 | D18: 1 | F18: 1
A19: 16 | C19: 2 | E19: 2
A20: 17 | D20: 1
A21: 18 | E21: 1
A22: 19
A23: 20 | C23: 2 | D23: 2 | E23: 2 | F23: 2
A24: 21 | C24: 2 | D24: 1 | E24: 2 | F24: 1
A25: 22 | C25: 1 | D25: 2 | E25: 1 | F25: 2
A26: 23 | C26: 1 | E26: 1
A27: 24 | D27: 2 | F27: 2
A28: 25 | D28: 1 | F28: 1
A29: 26 | C29: 2 | E29: 2
A30: 27 | D30: 1
A31: 28 | E31: 1
A32: 29
A33: 30 | C33: 2 | D33: 2 | E33: 2 | F33: 2
A34: 31 | C34: 2 | D34: 1 | E34: 2 | F34: 1
A35: 32 | C35: 1 | D35: 2 | E35: 1 | F35: 2
A36: 33 | C36: 1 | E36: 1
A37: 34 | D37: 2 | F37: 2
A38: 35 | D38: 1 | F38: 1
A39: 36 | C39: 2 | E39: 2
A40: 37 | D40: 1
...

Sheet CA3
A1: Sr. No. | B1: Name of Students | C1: Roll Number | D1: Group Number | E1: Topic(Presentation) | F1: Marks (Max per student = 10) | G1: COs (Enter COs as digits with comma e.g. 1,2) | H1: Count | I1: Count >= 50.0% | J1: % Count ( >= 50.0%) | K1: AL (Based on >= 50.0% Count)
A2: 1 | D2: 1 | F2: 10 | G2: 1 | H2: =COUNT(F2:F11) | I2: =COUNTIF(F2:F11,">=5.0") | J2: =ROUND((I2/H2)*100,1) | K2: =IF(J2<60,1,IF(AND(J2>59,J2<70),2,IF(AND(J2>69,J2<80),3,4)))
A3: 2 | D3: 1 | F3: 8
A4: 3 | D4: 1 | F4: 5
A5: 4 | D5: 1 | F5: 6
A6: 5 | D6: 1 | F6: 4
A7: 6 | D7: 1 | F7: 7
A8: 7 | D8: 1 | F8: 8
A9: 8 | D9: 1 | F9: 5
A10: 9 | D10: 1 | F10: 10
A11: 10 | D11: 1
A12: 11 | D12: 2 | F12: 10 | G12: 2 | H12: =COUNT(F12:F21) | I12: =COUNTIF(F12:F21,">=5.0") | J12: =ROUND((I12/H12)*100,1) | K12: =IF(J12<60,1,IF(AND(J12>59,J12<70),2,IF(AND(J12>69,J12<80),3,4)))
A13: 12 | D13: 2 | F13: 8
A14: 13 | D14: 2 | F14: 5
A15: 14 | D15: 2 | F15: 6
A16: 15 | D16: 2 | F16: 4
A17: 16 | D17: 2 | F17: 7
A18: 17 | D18: 2 | F18: 8
A19: 18 | D19: 2 | F19: 5
A20: 19 | D20: 2 | F20: 10
A21: 20 | D21: 2
A22: 21 | D22: 3 | F22: 10 | G22: 3 | H22: =COUNT(F22:F31) | I22: =COUNTIF(F22:F31,">=5.0") | J22: =ROUND((I22/H22)*100,1) | K22: =IF(J22<60,1,IF(AND(J22>59,J22<70),2,IF(AND(J22>69,J22<80),3,4)))
A23: 22 | D23: 3 | F23: 8
A24: 23 | D24: 3 | F24: 5
A25: 24 | D25: 3 | F25: 6
A26: 25 | D26: 3 | F26: 4
A27: 26 | D27: 3 | F27: 7
A28: 27 | D28: 3 | F28: 8
A29: 28 | D29: 3 | F29: 5
A30: 29 | D30: 3 | F30: 10
A31: 30 | D31: 3
A32: 31 | D32: 4 | F32: 10 | G32: 4 | H32: =COUNT(F32:F41) | I32: =COUNTIF(F32:F41,">=5.0") | J32: =ROUND((I32/H32)*100,1) | K32: =IF(J32<60,1,IF(AND(J32>59,J32<70),2,IF(AND(J32>69,J32<80),3,4)))
A33: 32 | D33: 4 | F33: 8
A34: 33 | D34: 4 | F34: 5
A35: 34 | D35: 4 | F35: 6
A36: 35 | D36: 4 | F36: 4
A37: 36 | D37: 4 | F37: 7
A38: 37 | D38: 4 | F38: 8
A39: 38 | D39: 4 | F39: 5
A40: 39 | D40: 4 | F40: 10
...

Sheet Survey
A1: Sr. No. | B1: Email Address | C1: Full name of Student | D1: Roll No. | E1: Class | F1: Branch | G1: Q1 | H1: Q2 | I1: Q3 | J1: Q4 | K1: Q5 | L1: Q6
A2: 1 | E2: D10A | F2: Information Technology | G2: 4 | H2: 5 | I2: 3 | J2: 4 | K2: 5 | L2: 2
A3: 2 | E3: D10A | F3: Information Technology | G3: 4 | H3: 5 | I3: 3 | J3: 4 | K3: 5 | L3: 2
A4: 3 | E4: D10A | F4: Information Technology | G4: 4 | H4: 5 | I4: 3 | J4: 4 | K4: 5 | L4: 2
A5: 4 | E5: D10A | F5: Information Technology | G5: 4 | H5: 5 | I5: 3 | J5: 4 | K5: 5 | L5: 2
A6: 5 | E6: D10A | F6: Information Technology | G6: 4 | H6: 5 | I6: 3 | J6: 4 | K6: 5 | L6: 2
A7: 6 | E7: D10A | F7: Information Technology | G7: 4 | H7: 5 | I7: 3 | J7: 4 | K7: 5 | L7: 2
A8: 7 | E8: D10A | F8: Information Technology | G8: 4 | H8: 5 | I8: 3 | J8: 4 | K8: 5 | L8: 2
A9: 8 | E9: D10A | F9: Information Technology | G9: 4 | H9: 5 | I9: 3 | J9: 4 | K9: 5 | L9: 2
A10: 9 | E10: D10A | F10: Information Technology | G10: 4 | H10: 5 | I10: 3 | J10: 4 | K10: 5 | L10: 2
A11: 10 | E11: D10A | F11: Information Technology | G11: 4 | H11: 5 | I11: 3 | J11: 4 | K11: 5 | L11: 2
A12: 11 | E12: D10A | F12: Information Technology | G12: 4 | H12: 5 | I12: 3 | J12: 4 | K12: 5 | L12: 2
A13: 12 | E13: D10A | F13: Information Technology | G13: 4 | H13: 5 | I13: 3 | J13: 4 | K13: 5 | L13: 2
... A61: 60 | E61: D10A | F61: Information Technology | G61: 4 | H61: 5 | I61: 3 | J61: 4 | K61: 5 | L61: 2
F64: Total | G64: =COUNT(G2:G61) | H64: =COUNT(H2:H61) | I64: =COUNT(I2:I61) | J64: =COUNT(J2:J61) | K64: =COUNT(K2:K61) | L64: =COUNT(L2:L61)
F65: SA + A Count | G65: =COUNTIF(G2:G61, ">=4") | H65: =COUNTIF(H2:H61, ">=4") | I65: =COUNTIF(I2:I61, ">=4") | J65: =COUNTIF(J2:J61, ">=4") | K65: =COUNTIF(K2:K61, ">=4") | L65: =COUNTIF(L2:L61, ">=4")
F66: SA + A Percentage | G66: =ROUND((G65/G64*100), 1) | H66: =ROUND((H65/H64*100), 1) | I66: =ROUND((I65/I64*100), 1) | J66: =ROUND((J65/J64*100), 1) | K66: =ROUND((K65/K64*100), 1) | L66: =ROUND((L65/L64*100), 1)
F67: CO Mapped | G67: CO1 | H67: CO2 | I67: CO3 | J67: CO4 | K67: CO5 | L67: CO6
F68: AL | G68: =IF(G66<60,1,IF(AND(G66>59,G66<70),2,IF(AND(G66>69,G66<80),3,4))) | H68: =IF(H66<60,1,IF(AND(H66>59,H66<70),2,IF(AND(H66>69,H66<80),3,4))) | I68: =IF(I66<60,1,IF(AND(I66>59,I66<70),2,IF(AND(I66>69,I66<80),3,4))) | J68: =IF(J66<60,1,IF(AND(J66>59,J66<70),2,IF(AND(J66>69,J66<80),3,4))) | K68: =IF(K66<60,1,IF(AND(K66>59,K66<70),2,IF(AND(K66>69,K66<80),3,4))) | L68: =IF(L66<60,1,IF(AND(L66>59,L66<70),2,IF(AND(L66>69,L66<80),3,4)))

Sheet Attainment
A1: Vivekanand Education Society's Institute of Technology
A2: Department of Information Technology
A3: Academic Year :2024-2025
A5: Subject : Data Structures and Analysis Class : D10A
A6: Subject Teacher :Sairam Konar Semester : III
A8: Course Outcomes(COs): Upon successful completion of this course, students will be able to:
A9: CO1 | B9: sairam
A10: CO2 | B10: konar
A11: CO3 | B11: d15c
A12: CO4 | B12: sariam
A13: CO5 | B13: sfabubo
A14: CO6 | B14: ve b
A16: CO Rubrics Mapping
A18: Assessment | B18: Direct Assessment | G18: Indirect Assessment
B19: Internal Assessment | F19: External Assessment
A20: CO's | B20: Mid Term Test | C20: CA1 | D20: CA2 | E20: CA3 | F20: ESE(TH) | G20: Course Exit Survey
A21: CO1 | B21: =IF(Midsem!G80="-"," ","✓") | C21: =IF(CA1!C77="-"," ","✓") | D21: =IF(CA2!D74="-"," ","✓") | E21: =IF(CA3!I67="-"," ","✓") | F21: =IF(Endsem!B74="-"," ","✓") | G21: =IF(Survey!G68="-"," ","✓")
A22: CO2 | B22: =IF(Midsem!G81="-"," ","✓") | C22: =IF(CA1!C78="-"," ","✓") | D22: =IF(CA2!D75="-"," ","✓") | E22: =IF(CA3!I68="-"," ","✓") | F22: =IF(Endsem!B75="-"," ","✓") | G22: =IF(Survey!H68="-"," ","✓")
A23: CO3 | B23: =IF(Midsem!G82="-"," ","✓") | C23: =IF(CA1!C79="-"," ","✓") | D23: =IF(CA2!D76="-"," ","✓") | E23: =IF(CA3!I69="-"," ","✓") | F23: =IF(Endsem!B76="-"," ","✓") | G23: =IF(Survey!I68="-"," ","✓")
A24: CO4 | B24: =IF(Midsem!G83="-"," ","✓") | C24: =IF(CA1!C80="-"," ","✓") | D24: =IF(CA2!D77="-"," ","✓") | E24: =IF(CA3!I70="-"," ","✓") | F24: =IF(Endsem!B77="-"," ","✓") | G24: =IF(Survey!J68="-"," ","✓")
A25: CO5 | B25: =IF(Midsem!G84="-"," ","✓") | C25: =IF(CA1!C81="-"," ","✓") | D25: =IF(CA2!D78="-"," ","✓") | E25: =IF(CA3!I71="-"," ","✓") | F25: =IF(Endsem!B78="-"," ","✓") | G25: =IF(Survey!K68="-"," ","✓")
A26: CO6 | B26: =IF(Midsem!G85="-"," ","✓") | C26: =IF(CA1!C82="-"," ","✓") | D26: =IF(CA2!D79="-"," ","✓") | E26: =IF(CA3!I72="-"," ","✓") | F26: =IF(Endsem!B79="-"," ","✓") | G26: =IF(Survey!L68="-"," ","✓")
A28: CO Attainment (Level)
A30: Assessment | B30: Direct Assessment | H30: Indirect Assessment
B31: Internal Assessment | F31: External Assessment | G31: Attainment Level
A32: CO's | B32: Mid Term Test | C32: CA1 | D32: CA2 | E32: CA3 | F32: ESE(TH) | G32: 70% (External) + 30% (Internal) | H32: Course Exit Survey
A33: CO1 | B33: =Midsem!G80 | C33: =CA1!C77 | D33: =CA2!D74 | E33: =CA3!I67 | F33: =Endsem!B74 | G33: =IF(AND(F33="-", COUNTIF(B33:E33, "-")=3), "-", IF(F33="-", ROUND(0.3*AVERAGE(B33,C33,D33,E33), 1), IF(COUNTIF(B33:E33, "-")=4, ROUND(0.7*F33, 1), ROUND(0.7*F33+0.3*(AVERAGE(B33,C33,D33,E33)),1)))) | H33: =Survey!G68
A34: CO2 | B34: =Midsem!G81 | C34: =CA1!C78 | D34: =CA2!D75 | E34: =CA3!I68 | F34: =Endsem!B75 | G34: =IF(AND(F34="-", COUNTIF(B34:E34, "-")=3), "-", IF(F34="-", ROUND(0.3*AVERAGE(B34,C34,D34,E34), 1), IF(COUNTIF(B34:E34, "-")=4, ROUND(0.7*F34, 1), ROUND(0.7*F34+0.3*(AVERAGE(B34,C34,D34,E34)),1)))) | H34: =Survey!H68
A35: CO3 | B35: =Midsem!G82 | C35: =CA1!C79 | D35: =CA2!D76 | E35: =CA3!I69 | F35: =Endsem!B76 | G35: =IF(AND(F35="-", COUNTIF(B35:E35, "-")=3), "-", IF(F35="-", ROUND(0.3*AVERAGE(B35,C35,D35,E35), 1), IF(COUNTIF(B35:E35, "-")=4, ROUND(0.7*F35, 1), ROUND(0.7*F35+0.3*(AVERAGE(B35,C35,D35,E35)),1)))) | H35: =Survey!I68
A36: CO4 | B36: =Midsem!G83 | C36: =CA1!C80 | D36: =CA2!D77 | E36: =CA3!I70 | F36: =Endsem!B77 | G36: =IF(AND(F36="-", COUNTIF(B36:E36, "-")=3), "-", IF(F36="-", ROUND(0.3*AVERAGE(B36,C36,D36,E36), 1), IF(COUNTIF(B36:E36, "-")=4, ROUND(0.7*F36, 1), ROUND(0.7*F36+0.3*(AVERAGE(B36,C36,D36,E36)),1)))) | H36: =Survey!J68
A37: CO5 | B37: =Midsem!G84 | C37: =CA1!C81 | D37: =CA2!D78 | E37: =CA3!I71 | F37: =Endsem!B78 | G37: =IF(AND(F37="-", COUNTIF(B37:E37, "-")=3), "-", IF(F37="-", ROUND(0.3*AVERAGE(B37,C37,D37,E37), 1), IF(COUNTIF(B37:E37, "-")=4, ROUND(0.7*F37, 1), ROUND(0.7*F37+0.3*(AVERAGE(B37,C37,D37,E37)),1)))) | H37: =Survey!K68
A38: CO6 | B38: =Midsem!G85 | C38: =CA1!C82 | D38: =CA2!D79 | E38: =CA3!I72 | F38: =Endsem!B79 | G38: =IF(AND(F38="-", COUNTIF(B38:E38, "-")=3), "-", IF(F38="-", ROUND(0.3*AVERAGE(B38,C38,D38,E38), 1), IF(COUNTIF(B38:E38, "-")=4, ROUND(0.7*F38, 1), ROUND(0.7*F38+0.3*(AVERAGE(B38,C38,D38,E38)),1)))) | H38: =Survey!L68
A40: Final CO Attainment
C42: Course Outcomes | D42: Direct AL | E42: Indirect AL
C43: CO1 | D43: =IF(AND(F33="-", COUNTIF(B33:E33, "-")=3), "-", IF(F33="-", ROUND(0.3*AVERAGE(B33,C33,D33,E33), 1), IF(COUNTIF(B33:E33, "-")=4, ROUND(0.7*F33, 1), ROUND(0.7*F33+0.3*(AVERAGE(B33,C33,D33,E33)),1)))) | E43: =Survey!G68
C44: CO2 | D44: =IF(AND(F34="-", COUNTIF(B34:E34, "-")=3), "-", IF(F34="-", ROUND(0.3*AVERAGE(B34,C34,D34,E34), 1), IF(COUNTIF(B34:E34, "-")=4, ROUND(0.7*F34, 1), ROUND(0.7*F34+0.3*(AVERAGE(B34,C34,D34,E34)),1)))) | E44: =Survey!H68
C45: CO3 | D45: =IF(AND(F35="-", COUNTIF(B35:E35, "-")=3), "-", IF(F35="-", ROUND(0.3*AVERAGE(B35,C35,D35,E35), 1), IF(COUNTIF(B35:E35, "-")=4, ROUND(0.7*F35, 1), ROUND(0.7*F35+0.3*(AVERAGE(B35,C35,D35,E35)),1)))) | E45: =Survey!I68
C46: CO4 | D46: =IF(AND(F36="-", COUNTIF(B36:E36, "-")=3), "-", IF(F36="-", ROUND(0.3*AVERAGE(B36,C36,D36,E36), 1), IF(COUNTIF(B36:E36, "-")=4, ROUND(0.7*F36, 1), ROUND(0.7*F36+0.3*(AVERAGE(B36,C36,D36,E36)),1)))) | E46: =Survey!J68
C47: CO5 | D47: =IF(AND(F37="-", COUNTIF(B37:E37, "-")=3), "-", IF(F37="-", ROUND(0.3*AVERAGE(B37,C37,D37,E37), 1), IF(COUNTIF(B37:E37, "-")=4, ROUND(0.7*F37, 1), ROUND(0.7*F37+0.3*(AVERAGE(B37,C37,D37,E37)),1)))) | E47: =Survey!K68
C48: CO6 | D48: =IF(AND(F38="-", COUNTIF(B38:E38, "-")=3), "-", IF(F38="-", ROUND(0.3*AVERAGE(B38,C38,D38,E38), 1), IF(COUNTIF(B38:E38, "-")=4, ROUND(0.7*F38, 1), ROUND(0.7*F38+0.3*(AVERAGE(B38,C38,D38,E38)),1)))) | E48: =Survey!L68

Sheet PO Attainment
A1: Vivekanand Education Society's Institute of Technology
A2: Department of Information Technology
A3: Academic Year :2024-2025
A5: Subject : Data Structures and Analysis Class : D10A
A6: Subject Teacher :Sairam Konar Semester : III
A9: Programme Outcomes(POs):
A10: PO1) Basic Engineering knowledge: An ability to apply the fundamental knowledge in mathematics, science and engineering to solve problems in Computer engineering. PO2) Problem Analysis: Identify, formulate, research literature and analyze computer engineering problems reaching substantiated conclusions using first principles of mathematics, natural sciences and computer engineering and sciences. PO3) Design/ Development of Solutions: Design solutions for complex computer engineering problems and design system components or processes that meet specified needs with appropriate consideration for public health and safety, cultural, societal and environmental considerations. PO4) Conduct investigations of complex engineering problems using research-based knowledge and research methods including design of experiments, analysis and interpretation of data and synthesis of information to provide valid conclusions PO5) Modern Tool Usage: Create, select and apply appropriate techniques, resources and modern computer engineering and IT tools including prediction and modeling to complex engineering activities with an understanding of the limitations. PO6) The Engineer and Society: Apply reasoning informed by contextual knowledge to assess societal, health, safety, legal and cultural issues and the consequent responsibilities relevant to computer engineering practice. PO7) Environment and Sustainability: Understand the impact of professional computer engineering solutions in societal and environmental contexts and demonstrate knowledge of and need for sustainable development. PO8) Ethics: Apply ethical principles and commit to professional ethics and responsibilities and norms of computer engineering practice. PO9) Individual and Team Work: Function effectively as an individual, and as a member or leader in diverse teams and in multidisciplinary settings. PO10) Communication: Communicate effectively on complex engineering activities with the engineering community and with society at large, such as being able to comprehend and write effective reports and design documentation, make effective presentations and give and receive clear instructions PO11) Project Management and Finance: Demonstrate knowledge and understanding of computer engineering and management principles and apply these to one's own work, as a member and leader in a team, to manage projects and in multidisciplinary environments. PO12) Life-long Learning: Recognize the need for and have the preparation and ability to engage in independent and lifelong learning in the broadest context of technological change. PSO1) Professional Skills - The ability to develop programs for computer based systems of varying complexity and domains using standard practices. PSO2) Successful Career - The ability to adopt skills, languages, environment and platforms for creating innovative carrier paths, being successful entrepreneurs or for pursuing higher studies.
A12: CO - PO/PSO Mapping
A14: Course Outcomes | B14: Programme Outcomes | N14: PSOs
B15: PO1 | C15: PO2 | D15: PO3 | E15: PO4 | F15: PO5 | G15: PO6 | H15: PO7 | I15: PO8 | J15: PO9 | K15: PO10 | L15: PO11 | M15: PO12 | N15: PSO1 | O15: PSO2
A16: CO1 | B16: 3 | C16: 0 | D16: 3 | E16: 3 | F16: 0 | G16: 3 | H16: 3 | I16: 3 | J16: 3 | K16: 3 | L16: 3 | M16: 3 | N16: 3 | O16: 3
A17: CO2 | B17: 0 | C17: 3 | D17: 3 | E17: 0 | F17: 0 | G17: 3 | H17: 0 | I17: 0 | J17: 3 | K17: 3 | L17: 0 | M17: 3 | N17: 3 | O17: 3
A18: CO3 | B18: 0 | C18: 0 | D18: 0 | E18: 0 | F18: 3 | G18: 0 | H18: 0 | I18: 0 | J18: 0 | K18: 0 | L18: 0 | M18: 3 | N18: 3 | O18: 3
A19: CO4 | B19: 3 | C19: 3 | D19: 3 | E19: 3 | F19: 3 | G19: 3 | H19: 3 | I19: 3 | J19: 3 | K19: 0 | L19: 3 | M19: 3 | N19: 3 | O19: 3
A20: CO5 | B20: 0 | C20: 3 | D20: 3 | E20: 3 | J20: 3 | K20: 3 | L20: 3 | M20: 3 | N20: 3 | O20: 3
A21: CO6 | B21: 0 | C21: 0 | D21: 0 | E21: 0 | F21: 2 | G21: 0 | H21: 0 | I21: 2 | J21: 0 | K21: 0 | L21: 0 | M21: 2 | N21: 2 | O21: 2
A23: Direct PO Attainment
A25: Course Outcomes(COs) | B25: Programme Outcomes(POs) | N25: PSOs
B26: PO1 | C26: PO2 | D26: PO3 | E26: PO4 | F26: PO5 | G26: PO6 | H26: PO7 | I26: PO8 | J26: PO9 | K26: PO10 | L26: PO11 | M26: PO12 | N26: PSO1 | O26: PSO2
A27: CO1 | B27: =Attainment!D43 | C27: =Attainment!D43 | D27: =Attainment!D43 | E27: =Attainment!D43 | F27: =Attainment!D43 | G27: =Attainment!D43 | H27: =Attainment!D43 | I27: =Attainment!D43 | J27: =Attainment!D43 | K27: =Attainment!D43 | L27: =Attainment!D43 | M27: =Attainment!D43 | N27: =Attainment!D43 | O27: =Attainment!D43
A28: CO2 | B28: =Attainment!D44 | C28: =Attainment!D44 | D28: =Attainment!D44 | E28: =Attainment!D44 | F28: =Attainment!D44 | G28: =Attainment!D44 | H28: =Attainment!D44 | I28: =Attainment!D44 | J28: =Attainment!D44 | K28: =Attainment!D44 | L28: =Attainment!D44 | M28: =Attainment!D44 | N28: =Attainment!D44 | O28: =Attainment!D44
A29: CO3 | B29: =Attainment!D45 | C29: =Attainment!D45 | D29: =Attainment!D45 | E29: =Attainment!D45 | F29: =Attainment!D45 | G29: =Attainment!D45 | H29: =Attainment!D45 | I29: =Attainment!D45 | J29: =Attainment!D45 | K29: =Attainment!D45 | L29: =Attainment!D45 | M29: =Attainment!D45 | N29: =Attainment!D45 | O29: =Attainment!D45
A30: CO4 | B30: =Attainment!D46 | C30: =Attainment!D46 | D30: =Attainment!D46 | E30: =Attainment!D46 | F30: =Attainment!D46 | G30: =Attainment!D46 | H30: =Attainment!D46 | I30: =Attainment!D46 | J30: =Attainment!D46 | K30: =Attainment!D46 | L30: =Attainment!D46 | M30: =Attainment!D46 | N30: =Attainment!D46 | O30: =Attainment!D46
A31: CO5 | B31: =Attainment!D47 | C31: =Attainment!D47 | D31: =Attainment!D47 | E31: =Attainment!D47 | F31: =Attainment!D47 | G31: =Attainment!D47 | H31: =Attainment!D47 | I31: =Attainment!D47 | J31: =Attainment!D47 | K31: =Attainment!D47 | L31: =Attainment!D47 | M31: =Attainment!D47 | N31: =Attainment!D47 | O31: =Attainment!D47
A32: CO6 | B32: =Attainment!D48 | C32: =Attainment!D48 | D32: =Attainment!D48 | E32: =Attainment!D48 | F32: =Attainment!D48 | G32: =Attainment!D48 | H32: =Attainment!D48 | I32: =Attainment!D48 | J32: =Attainment!D48 | K32: =Attainment!D48 | L32: =Attainment!D48 | M32: =Attainment!D48 | N32: =Attainment!D48 | O32: =Attainment!D48
A34: Direct PO Attainment (After Applying CO-PO Mapping)
A36: Course Outcomes(COs) | B36: Programme Outcomes(POs) | N36: PSOs
B37: PO1 | C37: PO2 | D37: PO3 | E37: PO4 | F37: PO5 | G37: PO6 | H37: PO7 | I37: PO8 | J37: PO9 | K37: PO10 | L37: PO11 | M37: PO12 | N37: PSO1 | O37: PSO2
A38: CO1 | B38: =IF(B16=3, B27, IF(B16=2, B27*0.6, IF(B16=1, B27*0.4, 0))) | C38: =IF(C16=3, C27, IF(C16=2, C27*0.6, IF(C16=1, C27*0.4, 0))) | D38: =IF(D16=3, D27, IF(D16=2, D27*0.6, IF(D16=1, D27*0.4, 0))) | E38: =IF(E16=3, E27, IF(E16=2, E27*0.6, IF(E16=1, E27*0.4, 0))) | F38: =IF(F16=3, F27, IF(F16=2, F27*0.6, IF(F16=1, F27*0.4, 0))) | G38: =IF(G16=3, G27, IF(G16=2, G27*0.6, IF(G16=1, G27*0.4, 0))) | H38: =IF(H16=3, H27, IF(H16=2, H27*0.6, IF(H16=1, H27*0.4, 0))) | I38: =IF(I16=3, I27, IF(I16=2, I27*0.6, IF(I16=1, I27*0.4, 0))) | ... O38: =IF(O16=3, O27, IF(O16=2, O27*0.6, IF(O16=1, O27*0.4, 0)))
A39: CO2 | B39: =IF(B17=3, B28, IF(B17=2, B28*0.6, IF(B17=1, B28*0.4, 0))) | C39: =IF(C17=3, C28, IF(C17=2, C28*0.6, IF(C17=1, C28*0.4, 0))) | D39: =IF(D17=3, D28, IF(D17=2, D28*0.6, IF(D17=1, D28*0.4, 0))) | E39: =IF(E17=3, E28, IF(E17=2, E28*0.6, IF(E17=1, E28*0.4, 0))) | F39: =IF(F17=3, F28, IF(F17=2, F28*0.6, IF(F17=1, F28*0.4, 0))) | G39: =IF(G17=3, G28, IF(G17=2, G28*0.6, IF(G17=1, G28*0.4, 0))) | H39: =IF(H17=3, H28, IF(H17=2, H28*0.6, IF(H17=1, H28*0.4, 0))) | I39: =IF(I17=3, I28, IF(I17=2, I28*0.6, IF(I17=1, I28*0.4, 0))) | ... O39: =IF(O17=3, O28, IF(O17=2, O28*0.6, IF(O17=1, O28*0.4, 0)))
A40: CO3 | B40: =IF(B18=3, B29, IF(B18=2, B29*0.6, IF(B18=1, B29*0.4, 0))) | C40: =IF(C18=3, C29, IF(C18=2, C29*0.6, IF(C18=1, C29*0.4, 0))) | D40: =IF(D18=3, D29, IF(D18=2, D29*0.6, IF(D18=1, D29*0.4, 0))) | E40: =IF(E18=3, E29, IF(E18=2, E29*0.6, IF(E18=1, E29*0.4, 0))) | F40: =IF(F18=3, F29, IF(F18=2, F29*0.6, IF(F18=1, F29*0.4, 0))) | G40: =IF(G18=3, G29, IF(G18=2, G29*0.6, IF(G18=1, G29*0.4, 0))) | H40: =IF(H18=3, H29, IF(H18=2, H29*0.6, IF(H18=1, H29*0.4, 0))) | I40: =IF(I18=3, I29, IF(I18=2, I29*0.6, IF(I18=1, I29*0.4, 0))) | ... O40: =IF(O18=3, O29, IF(O18=2, O29*0.6, IF(O18=1, O29*0.4, 0)))
A41: CO4 | B41: =IF(B19=3, B30, IF(B19=2, B30*0.6, IF(B19=1, B30*0.4, 0))) | C41: =IF(C19=3, C30, IF(C19=2, C30*0.6, IF(C19=1, C30*0.4, 0))) | D41: =IF(D19=3, D30, IF(D19=2, D30*0.6, IF(D19=1, D30*0.4, 0))) | E41: =IF(E19=3, E30, IF(E19=2, E30*0.6, IF(E19=1, E30*0.4, 0))) | F41: =IF(F19=3, F30, IF(F19=2, F30*0.6, IF(F19=1, F30*0.4, 0))) | G41: =IF(G19=3, G30, IF(G19=2, G30*0.6, IF(G19=1, G30*0.4, 0))) | H41: =IF(H19=3, H30, IF(H19=2, H30*0.6, IF(H19=1, H30*0.4, 0))) | I41: =IF(I19=3, I30, IF(I19=2, I30*0.6, IF(I19=1, I30*0.4, 0))) | ... O41: =IF(O19=3, O30, IF(O19=2, O30*0.6, IF(O19=1, O30*0.4, 0)))
A42: CO5 | B42: =IF(B20=3, B31, IF(B20=2, B31*0.6, IF(B20=1, B31*0.4, 0))) | C42: =IF(C20=3, C31, IF(C20=2, C31*0.6, IF(C20=1, C31*0.4, 0))) | D42: =IF(D20=3, D31, IF(D20=2, D31*0.6, IF(D20=1, D31*0.4, 0))) | E42: =IF(E20=3, E31, IF(E20=2, E31*0.6, IF(E20=1, E31*0.4, 0))) | J42: =IF(J20=3, J31, IF(J20=2, J31*0.6, IF(J20=1, J31*0.4, 0))) | K42: =IF(K20=3, K31, IF(K20=2, K31*0.6, IF(K20=1, K31*0.4, 0))) | L42: =IF(L20=3, L31, IF(L20=2, L31*0.6, IF(L20=1, L31*0.4, 0))) | M42: =IF(M20=3, M31, IF(M20=2, M31*0.6, IF(M20=1, M31*0.4, 0))) | N42: =IF(N20=3, N31, IF(N20=2, N31*0.6, IF(N20=1, N31*0.4, 0))) | O42: =IF(O20=3, O31, IF(O20=2, O31*0.6, IF(O20=1, O31*0.4, 0)))
A43: CO6 | B43: =IF(B21=3, B32, IF(B21=2, B32*0.6, IF(B21=1, B32*0.4, 0))) | C43: =IF(C21=3, C32, IF(C21=2, C32*0.6, IF(C21=1, C32*0.4, 0))) | D43: =IF(D21=3, D32, IF(D21=2, D32*0.6, IF(D21=1, D32*0.4, 0))) | E43: =IF(E21=3, E32, IF(E21=2, E32*0.6, IF(E21=1, E32*0.4, 0))) | F43: =IF(F21=3, F32, IF(F21=2, F32*0.6, IF(F21=1, F32*0.4, 0))) | G43: =IF(G21=3, G32, IF(G21=2, G32*0.6, IF(G21=1, G32*0.4, 0))) | H43: =IF(H21=3, H32, IF(H21=2, H32*0.6, IF(H21=1, H32*0.4, 0))) | I43: =IF(I21=3, I32, IF(I21=2, I32*0.6, IF(I21=1, I32*0.4, 0))) | ... O43: =IF(O21=3, O32, IF(O21=2, O32*0.6, IF(O21=1, O32*0.4, 0)))
A44: Avg PO | B44: =ROUND(AVERAGE(B38:B43),1) | C44: =ROUND(AVERAGE(C38:C43),1) | D44: =ROUND(AVERAGE(D38:D43),1) | E44: =ROUND(AVERAGE(E38:E43),1) | F44: =ROUND(AVERAGE(F38:F43),1) | G44: =ROUND(AVERAGE(G38:G43),1) | H44: =ROUND(AVERAGE(H38:H43),1) | I44: =ROUND(AVERAGE(I38:I43),1) | ... O44: =ROUND(AVERAGE(O38:O43),1)
A47: AL | B47: %
A48: 1 | B48: 40
A49: 2 | B49: 60
A50: 3 | B50: 100

Sheet CO Information
A1: Basic Information
A3: TargetCA1Text | B3: 40
A4: TargetCA2Text | B4: 45
A5: TargetCA3Text | B5: 50
A6: TargetMidTermText | B6: 52.5
A7: TargetEndSemText | B7: 60
A9: No. of COs | B9: 6
